Workbook

Sheet Instrucciones
B2: Fantasy de Clase — Guia de uso
B3: Plantilla para gestionar el Fantasy con 24 alumnos, plantillas de 5 jugadores y capitan.
B5: 1. Alumnos
B6: Escribe el nombre real de cada uno de los 24 alumnos en la hoja 'Alumnos' (celdas en amarillo). No cambies los ID.
B8: 2. Config_Puntos
B9: Ajusta el nombre y los puntos de cada evento puntuable en 'Config_Puntos' (celdas en amarillo). Puedes anadir filas nuevas si necesitas mas eventos, siguiendo el mismo formato.
B11: 3. Calendario
B12: Muestra las 12 jornadas de 2 semanas entre el 21/09/2026 y el 05/03/2027 (la ultima dura 12 dias para cuadrar con el fin de temporada), con la fecha de apertura y cierre (24h) de cada ventana de fichajes. Si cambias las fechas de inicio/fin en B1/B2, las jornadas se recalculan solas.
B14: 4. Eventos
B15: Cada vez que ocurra algo puntuable (participacion, entrega, examen, etc.) registra una fila en 'Eventos': fecha, jornada (1-12), alumno y tipo de evento. Los puntos se calculan solos.
B17: 5. Puntos_Jornada
B18: Se calcula automaticamente: total de puntos de cada alumno en cada jornada, a partir de la hoja 'Eventos'. No editar a mano.
... B34: - El capitan duplica su puntuacion: se suma su puntuacion una vez extra sobre el total de los 5 jugadores.

Sheet Alumnos
A1: ID | B1: Nombre | C1: Valor J2 | D1: Valor J1
A2: 1 | B2: Alumno 1 | C2: 25 | D2: 20
A3: 2 | B3: Alumno 2 | D3: 20
A4: 3 | B4: Alumno 3 | D4: 20
A5: 4 | B5: Alumno 4 | D5: 20
A6: 5 | B6: Alumno 5 | D6: 20
A7: 6 | B7: Alumno 6 | D7: 20
A8: 7 | B8: Alumno 7 | D8: 20
A9: 8 | B9: Alumno 8 | D9: 20
A10: 9 | B10: Alumno 9 | D10: 20
A11: 10 | B11: Alumno 10 | D11: 20
A12: 11 | B12: Alumno 11 | D12: 20
A13: 12 | B13: Alumno 12 | D13: 20
A14: 13 | B14: Alumno 13 | D14: 20
... A25: 24 | B25: Alumno 24 | D25: 20

Sheet Config_Puntos
A1: Evento | B1: Puntos
A2: Mejora respecto al anterior examen | B2: 6
A3: Examen >9 | B3: 6
A4: Trabajo >9 | B4: 5
A5: Examen 7>X<9 | B5: 4
A6: Trabajo 7>X<9 | B6: 3
A7: Participacion voluntaria (diversas formas) | B7: 2
A8: Nota examen por encima de la media | B8: 2
A9: Ayuda a un companero | B9: 2
A10: No ha tenido ausencias en la jornada | B10: 2
A11: Trabajo 6>X<7 | B11: 2
A12: Examen 6>X<7 | B12: 2
A13: Entrega de tarea a tiempo | B13: 1
... A21: Trabajo/Examen no entregado | B21: -10

Sheet Calendario
A1: Fecha inicio temporada | B1: 46286
A2: Fecha fin temporada | B2: 46451
A4: Jornada | B4: Fecha inicio jornada | C4: Fecha fin jornada | D4: Apertura ventana fichajes | E4: Cierre ventana fichajes (24h)
A5: 1 | B5: =$B$1 -> 46286 | C5: =MIN(B5+13,$B$2) -> 46299 | D5: =B5 -> 46286 | E5: =B5+1 -> 46287
A6: 2 | B6: =C5+1 -> 46300 | C6: =MIN(B6+13,$B$2) -> 46313 | D6: =B6 -> 46300 | E6: =B6+1 -> 46301
A7: 3 | B7: =C6+1 -> 46314 | C7: =MIN(B7+13,$B$2) -> 46327 | D7: =B7 -> 46314 | E7: =B7+1 -> 46315
A8: 4 | B8: =C7+1 -> 46328 | C8: =MIN(B8+13,$B$2) -> 46341 | D8: =B8 -> 46328 | E8: =B8+1 -> 46329
A9: 5 | B9: =C8+1 -> 46342 | C9: =MIN(B9+13,$B$2) -> 46355 | D9: =B9 -> 46342 | E9: =B9+1 -> 46343
A10: 6 | B10: =C9+1 -> 46356 | C10: =MIN(B10+13,$B$2) -> 46369 | D10: =B10 -> 46356 | E10: =B10+1 -> 46357
A11: 7 | B11: =C10+1 -> 46370 | C11: =MIN(B11+13,$B$2) -> 46383 | D11: =B11 -> 46370 | E11: =B11+1 -> 46371
A12: 8 | B12: =C11+1 -> 46384 | C12: =MIN(B12+13,$B$2) -> 46397 | D12: =B12 -> 46384 | E12: =B12+1 -> 46385 | F12: J sin cambios: Navidad
A13: 9 | B13: =C12+1 -> 46398 | C13: =MIN(B13+13,$B$2) -> 46411 | D13: =B13 -> 46398 | E13: =B13+1 -> 46399
A14: 10 | B14: =C13+1 -> 46412 | C14: =MIN(B14+13,$B$2) -> 46425 | D14: =B14 -> 46412 | E14: =B14+1 -> 46413
A15: 11 | B15: =C14+1 -> 46426 | C15: =MIN(B15+13,$B$2) -> 46439 | D15: =B15 -> 46426 | E15: =B15+1 -> 46427
A16: 12 | B16: =C15+1 -> 46440 | C16: =MIN(B16+13,$B$2) -> 46451 | D16: =B16 -> 46440 | E16: =B16+1 -> 46441

Sheet Eventos
A1: Fecha | B1: Jornada | C1: Alumno | D1: Evento | E1: Puntos | F1: Comentario
A2: 46287 | B2: 1 | C2: Alumno 1 | D2: Mejora respecto al anterior examen | E2: =IFERROR(INDEX(Config_Puntos!$B$2:$B$18,MATCH(D2,Config_Puntos!$A$2:$A$18,0)),"") -> 6
A3: 46287 | B3: 1 | C3: Alumno 1 | D3: Participacion voluntaria (diversas formas) | E3: =IFERROR(INDEX(Config_Puntos!$B$2:$B$18,MATCH(D3,Config_Puntos!$A$2:$A$18,0)),"") -> 2
E4: =IFERROR(INDEX(Config_Puntos!$B$2:$B$18,MATCH(D4,Config_Puntos!$A$2:$A$18,0)),"")
E5: =IFERROR(INDEX(Config_Puntos!$B$2:$B$18,MATCH(D5,Config_Puntos!$A$2:$A$18,0)),"")
E6: =IFERROR(INDEX(Config_Puntos!$B$2:$B$18,MATCH(D6,Config_Puntos!$A$2:$A$18,0)),"")
E7: =IFERROR(INDEX(Config_Puntos!$B$2:$B$18,MATCH(D7,Config_Puntos!$A$2:$A$18,0)),"")
E8: =IFERROR(INDEX(Config_Puntos!$B$2:$B$18,MATCH(D8,Config_Puntos!$A$2:$A$18,0)),"")
E9: =IFERROR(INDEX(Config_Puntos!$B$2:$B$18,MATCH(D9,Config_Puntos!$A$2:$A$18,0)),"")
E10: =IFERROR(INDEX(Config_Puntos!$B$2:$B$18,MATCH(D10,Config_Puntos!$A$2:$A$18,0)),"")
E11: =IFERROR(INDEX(Config_Puntos!$B$2:$B$18,MATCH(D11,Config_Puntos!$A$2:$A$18,0)),"")
E12: =IFERROR(INDEX(Config_Puntos!$B$2:$B$18,MATCH(D12,Config_Puntos!$A$2:$A$18,0)),"")
E13: =IFERROR(INDEX(Config_Puntos!$B$2:$B$18,MATCH(D13,Config_Puntos!$A$2:$A$18,0)),"")
E14: =IFERROR(INDEX(Config_Puntos!$B$2:$B$18,MATCH(D14,Config_Puntos!$A$2:$A$18,0)),"")
E15: =IFERROR(INDEX(Config_Puntos!$B$2:$B$18,MATCH(D15,Config_Puntos!$A$2:$A$18,0)),"")
... E401: =IFERROR(INDEX(Config_Puntos!$B$2:$B$18,MATCH(D401,Config_Puntos!$A$2:$A$18,0)),"")

Sheet Plantillas
A1: Jornada | B1: Manager | C1: Jugador 1 | D1: Jugador 2 | E1: Jugador 3 | F1: Jugador 4 | G1: Jugador 5 | H1: Capitan | I1: V1 | J1: V2 | K1: V3 | L1: V4 | M1: V5 | N1: Valor plantilla | O1: Manager en su propia plantilla? | P1: Capitan valido? | Q1: Fecha inicio jornada | R1: Fecha fin jornada | S1: Ventana de fichajes
A2: 1 | B2: =Alumnos!B2 -> Alumno 1 | C2: =B2 -> Alumno 1 | D2: Alumno 3 | E2: Alumno 4 | F2: Alumno 1 | G2: Alumno 10 | H2: Alumno 1 | I2: =VLOOKUP(C2,Alumnos!$B:$D,2,FALSE) -> 25 | J2: =VLOOKUP(D2,Alumnos!$B:$D,2,FALSE) -> 0 | K2: =VLOOKUP(E2,Alumnos!$B:$D,2,FALSE) -> 0 | L2: =VLOOKUP(F2,Alumnos!$B:$D,2,FALSE) -> 25 | M2: =VLOOKUP(G2,Alumnos!$B:$D,2,FALSE) -> 0 | N2: =SUM(I2:M2) -> 50 | O2: =IF(OR($B2=$C2,$B2=$D2,$B2=$E2,$B2=$F2,$B2=$G2),"OK","FALTA") -> OK | P2: =IF(OR($H2=$C2,$H2=$D2,$H2=$E2,$H2=$F2,$H2=$G2),"OK","ERROR") -> OK | Q2: =INDEX(Calendario!$B$5:$B$16,MATCH($A2,Calendario!$A$5:$A$16,0)) -> 46286 | R2: =INDEX(Calendario!$C$5:$C$16,MATCH($A2,Calendario!$A$5:$A$16,0)) -> 46299 | S2: =TEXT(Q2,"DD/MM/YYYY")&" - "&TEXT(Q2+1,"DD/MM/YYYY") -> 21/09/YYYY - 22/09/YYYY
A3: 1 | B3: =Alumnos!B3 -> Alumno 2 | O3: =IF(OR($B3=$C3,$B3=$D3,$B3=$E3,$B3=$F3,$B3=$G3),"OK","FALTA") -> FALTA | P3: =IF(OR($H3=$C3,$H3=$D3,$H3=$E3,$H3=$F3,$H3=$G3),"OK","ERROR") -> OK | Q3: =INDEX(Calendario!$B$5:$B$16,MATCH($A3,Calendario!$A$5:$A$16,0)) -> 46286 | R3: =INDEX(Calendario!$C$5:$C$16,MATCH($A3,Calendario!$A$5:$A$16,0)) -> 46299 | S3: =TEXT(Q3,"DD/MM/YYYY")&" - "&TEXT(Q3+1,"DD/MM/YYYY") -> 21/09/YYYY - 22/09/YYYY
A4: 1 | B4: =Alumnos!B4 -> Alumno 3 | O4: =IF(OR($B4=$C4,$B4=$D4,$B4=$E4,$B4=$F4,$B4=$G4),"OK","FALTA") -> FALTA | P4: =IF(OR($H4=$C4,$H4=$D4,$H4=$E4,$H4=$F4,$H4=$G4),"OK","ERROR") -> OK | Q4: =INDEX(Calendario!$B$5:$B$16,MATCH($A4,Calendario!$A$5:$A$16,0)) -> 46286 | R4: =INDEX(Calendario!$C$5:$C$16,MATCH($A4,Calendario!$A$5:$A$16,0)) -> 46299 | S4: =TEXT(Q4,"DD/MM/YYYY")&" - "&TEXT(Q4+1,"DD/MM/YYYY") -> 21/09/YYYY - 22/09/YYYY
A5: 1 | B5: =Alumnos!B5 -> Alumno 4 | O5: =IF(OR($B5=$C5,$B5=$D5,$B5=$E5,$B5=$F5,$B5=$G5),"OK","FALTA") -> FALTA | P5: =IF(OR($H5=$C5,$H5=$D5,$H5=$E5,$H5=$F5,$H5=$G5),"OK","ERROR") -> OK | Q5: =INDEX(Calendario!$B$5:$B$16,MATCH($A5,Calendario!$A$5:$A$16,0)) -> 46286 | R5: =INDEX(Calendario!$C$5:$C$16,MATCH($A5,Calendario!$A$5:$A$16,0)) -> 46299 | S5: =TEXT(Q5,"DD/MM/YYYY")&" - "&TEXT(Q5+1,"DD/MM/YYYY") -> 21/09/YYYY - 22/09/YYYY
A6: 1 | B6: =Alumnos!B6 -> Alumno 5 | O6: =IF(OR($B6=$C6,$B6=$D6,$B6=$E6,$B6=$F6,$B6=$G6),"OK","FALTA") -> FALTA | P6: =IF(OR($H6=$C6,$H6=$D6,$H6=$E6,$H6=$F6,$H6=$G6),"OK","ERROR") -> OK | Q6: =INDEX(Calendario!$B$5:$B$16,MATCH($A6,Calendario!$A$5:$A$16,0)) -> 46286 | R6: =INDEX(Calendario!$C$5:$C$16,MATCH($A6,Calendario!$A$5:$A$16,0)) -> 46299 | S6: =TEXT(Q6,"DD/MM/YYYY")&" - "&TEXT(Q6+1,"DD/MM/YYYY") -> 21/09/YYYY - 22/09/YYYY
A7: 1 | B7: =Alumnos!B7 -> Alumno 6 | O7: =IF(OR($B7=$C7,$B7=$D7,$B7=$E7,$B7=$F7,$B7=$G7),"OK","FALTA") -> FALTA | P7: =IF(OR($H7=$C7,$H7=$D7,$H7=$E7,$H7=$F7,$H7=$G7),"OK","ERROR") -> OK | Q7: =INDEX(Calendario!$B$5:$B$16,MATCH($A7,Calendario!$A$5:$A$16,0)) -> 46286 | R7: =INDEX(Calendario!$C$5:$C$16,MATCH($A7,Calendario!$A$5:$A$16,0)) -> 46299 | S7: =TEXT(Q7,"DD/MM/YYYY")&" - "&TEXT(Q7+1,"DD/MM/YYYY") -> 21/09/YYYY - 22/09/YYYY
A8: 1 | B8: =Alumnos!B8 -> Alumno 7 | O8: =IF(OR($B8=$C8,$B8=$D8,$B8=$E8,$B8=$F8,$B8=$G8),"OK","FALTA") -> FALTA | P8: =IF(OR($H8=$C8,$H8=$D8,$H8=$E8,$H8=$F8,$H8=$G8),"OK","ERROR") -> OK | Q8: =INDEX(Calendario!$B$5:$B$16,MATCH($A8,Calendario!$A$5:$A$16,0)) -> 46286 | R8: =INDEX(Calendario!$C$5:$C$16,MATCH($A8,Calendario!$A$5:$A$16,0)) -> 46299 | S8: =TEXT(Q8,"DD/MM/YYYY")&" - "&TEXT(Q8+1,"DD/MM/YYYY") -> 21/09/YYYY - 22/09/YYYY
A9: 1 | B9: =Alumnos!B9 -> Alumno 8 | O9: =IF(OR($B9=$C9,$B9=$D9,$B9=$E9,$B9=$F9,$B9=$G9),"OK","FALTA") -> FALTA | P9: =IF(OR($H9=$C9,$H9=$D9,$H9=$E9,$H9=$F9,$H9=$G9),"OK","ERROR") -> OK | Q9: =INDEX(Calendario!$B$5:$B$16,MATCH($A9,Calendario!$A$5:$A$16,0)) -> 46286 | R9: =INDEX(Calendario!$C$5:$C$16,MATCH($A9,Calendario!$A$5:$A$16,0)) -> 46299 | S9: =TEXT(Q9,"DD/MM/YYYY")&" - "&TEXT(Q9+1,"DD/MM/YYYY") -> 21/09/YYYY - 22/09/YYYY
A10: 1 | B10: =Alumnos!B10 -> Alumno 9 | O10: =IF(OR($B10=$C10,$B10=$D10,$B10=$E10,$B10=$F10,$B10=$G10),"OK","FALTA") -> FALTA | P10: =IF(OR($H10=$C10,$H10=$D10,$H10=$E10,$H10=$F10,$H10=$G10),"OK","ERROR") -> OK | Q10: =INDEX(Calendario!$B$5:$B$16,MATCH($A10,Calendario!$A$5:$A$16,0)) -> 46286 | R10: =INDEX(Calendario!$C$5:$C$16,MATCH($A10,Calendario!$A$5:$A$16,0)) -> 46299 | S10: =TEXT(Q10,"DD/MM/YYYY")&" - "&TEXT(Q10+1,"DD/MM/YYYY") -> 21/09/YYYY - 22/09/YYYY
A11: 1 | B11: =Alumnos!B11 -> Alumno 10 | O11: =IF(OR($B11=$C11,$B11=$D11,$B11=$E11,$B11=$F11,$B11=$G11),"OK","FALTA") -> FALTA | P11: =IF(OR($H11=$C11,$H11=$D11,$H11=$E11,$H11=$F11,$H11=$G11),"OK","ERROR") -> OK | Q11: =INDEX(Calendario!$B$5:$B$16,MATCH($A11,Calendario!$A$5:$A$16,0)) -> 46286 | R11: =INDEX(Calendario!$C$5:$C$16,MATCH($A11,Calendario!$A$5:$A$16,0)) -> 46299 | S11: =TEXT(Q11,"DD/MM/YYYY")&" - "&TEXT(Q11+1,"DD/MM/YYYY") -> 21/09/YYYY - 22/09/YYYY
A12: 1 | B12: =Alumnos!B12 -> Alumno 11 | O12: =IF(OR($B12=$C12,$B12=$D12,$B12=$E12,$B12=$F12,$B12=$G12),"OK","FALTA") -> FALTA | P12: =IF(OR($H12=$C12,$H12=$D12,$H12=$E12,$H12=$F12,$H12=$G12),"OK","ERROR") -> OK | Q12: =INDEX(Calendario!$B$5:$B$16,MATCH($A12,Calendario!$A$5:$A$16,0)) -> 46286 | R12: =INDEX(Calendario!$C$5:$C$16,MATCH($A12,Calendario!$A$5:$A$16,0)) -> 46299 | S12: =TEXT(Q12,"DD/MM/YYYY")&" - "&TEXT(Q12+1,"DD/MM/YYYY") -> 21/09/YYYY - 22/09/YYYY
A13: 1 | B13: =Alumnos!B13 -> Alumno 12 | O13: =IF(OR($B13=$C13,$B13=$D13,$B13=$E13,$B13=$F13,$B13=$G13),"OK","FALTA") -> FALTA | P13: =IF(OR($H13=$C13,$H13=$D13,$H13=$E13,$H13=$F13,$H13=$G13),"OK","ERROR") -> OK | Q13: =INDEX(Calendario!$B$5:$B$16,MATCH($A13,Calendario!$A$5:$A$16,0)) -> 46286 | R13: =INDEX(Calendario!$C$5:$C$16,MATCH($A13,Calendario!$A$5:$A$16,0)) -> 46299 | S13: =TEXT(Q13,"DD/MM/YYYY")&" - "&TEXT(Q13+1,"DD/MM/YYYY") -> 21/09/YYYY - 22/09/YYYY
A14: 1 | B14: =Alumnos!B14 -> Alumno 13 | O14: =IF(OR($B14=$C14,$B14=$D14,$B14=$E14,$B14=$F14,$B14=$G14),"OK","FALTA") -> FALTA | P14: =IF(OR($H14=$C14,$H14=$D14,$H14=$E14,$H14=$F14,$H14=$G14),"OK","ERROR") -> OK | Q14: =INDEX(Calendario!$B$5:$B$16,MATCH($A14,Calendario!$A$5:$A$16,0)) -> 46286 | R14: =INDEX(Calendario!$C$5:$C$16,MATCH($A14,Calendario!$A$5:$A$16,0)) -> 46299 | S14: =TEXT(Q14,"DD/MM/YYYY")&" - "&TEXT(Q14+1,"DD/MM/YYYY") -> 21/09/YYYY - 22/09/YYYY
... A25: 1 | B25: =Alumnos!B25 -> Alumno 24 | O25: =IF(OR($B25=$C25,$B25=$D25,$B25=$E25,$B25=$F25,$B25=$G25),"OK","FALTA") -> FALTA | P25: =IF(OR($H25=$C25,$H25=$D25,$H25=$E25,$H25=$F25,$H25=$G25),"OK","ERROR") -> OK | Q25: =INDEX(Calendario!$B$5:$B$16,MATCH($A25,Calendario!$A$5:$A$16,0)) -> 46286 | R25: =INDEX(Calendario!$C$5:$C$16,MATCH($A25,Calendario!$A$5:$A$16,0)) -> 46299 | S25: =TEXT(Q25,"DD/MM/YYYY")&" - "&TEXT(Q25+1,"DD/MM/YYYY") -> 21/09/YYYY - 22/09/YYYY
A26: 2 | B26: =Alumnos!B2 -> Alumno 1 | O26: =IF(OR($B26=$C26,$B26=$D26,$B26=$E26,$B26=$F26,$B26=$G26),"OK","FALTA") -> FALTA | P26: =IF(OR($H26=$C26,$H26=$D26,$H26=$E26,$H26=$F26,$H26=$G26),"OK","ERROR") -> OK | Q26: =INDEX(Calendario!$B$5:$B$16,MATCH($A26,Calendario!$A$5:$A$16,0)) -> 46300 | R26: =INDEX(Calendario!$C$5:$C$16,MATCH($A26,Calendario!$A$5:$A$16,0)) -> 46313 | S26: =TEXT(Q26,"DD/MM/YYYY")&" - "&TEXT(Q26+1,"DD/MM/YYYY") -> 05/10/YYYY - 06/10/YYYY
A27: 2 | B27: =Alumnos!B3 -> Alumno 2 | O27: =IF(OR($B27=$C27,$B27=$D27,$B27=$E27,$B27=$F27,$B27=$G27),"OK","FALTA") -> FALTA | P27: =IF(OR($H27=$C27,$H27=$D27,$H27=$E27,$H27=$F27,$H27=$G27),"OK","ERROR") -> OK | Q27: =INDEX(Calendario!$B$5:$B$16,MATCH($A27,Calendario!$A$5:$A$16,0)) -> 46300 | R27: =INDEX(Calendario!$C$5:$C$16,MATCH($A27,Calendario!$A$5:$A$16,0)) -> 46313 | S27: =TEXT(Q27,"DD/MM/YYYY")&" - "&TEXT(Q27+1,"DD/MM/YYYY") -> 05/10/YYYY - 06/10/YYYY
A28: 2 | B28: =Alumnos!B4 -> Alumno 3 | O28: =IF(OR($B28=$C28,$B28=$D28,$B28=$E28,$B28=$F28,$B28=$G28),"OK","FALTA") -> FALTA | P28: =IF(OR($H28=$C28,$H28=$D28,$H28=$E28,$H28=$F28,$H28=$G28),"OK","ERROR") -> OK | Q28: =INDEX(Calendario!$B$5:$B$16,MATCH($A28,Calendario!$A$5:$A$16,0)) -> 46300 | R28: =INDEX(Calendario!$C$5:$C$16,MATCH($A28,Calendario!$A$5:$A$16,0)) -> 46313 | S28: =TEXT(Q28,"DD/MM/YYYY")&" - "&TEXT(Q28+1,"DD/MM/YYYY") -> 05/10/YYYY - 06/10/YYYY
A29: 2 | B29: =Alumnos!B5 -> Alumno 4 | O29: =IF(OR($B29=$C29,$B29=$D29,$B29=$E29,$B29=$F29,$B29=$G29),"OK","FALTA") -> FALTA | P29: =IF(OR($H29=$C29,$H29=$D29,$H29=$E29,$H29=$F29,$H29=$G29),"OK","ERROR") -> OK | Q29: =INDEX(Calendario!$B$5:$B$16,MATCH($A29,Calendario!$A$5:$A$16,0)) -> 46300 | R29: =INDEX(Calendario!$C$5:$C$16,MATCH($A29,Calendario!$A$5:$A$16,0)) -> 46313 | S29: =TEXT(Q29,"DD/MM/YYYY")&" - "&TEXT(Q29+1,"DD/MM/YYYY") -> 05/10/YYYY - 06/10/YYYY
A30: 2 | B30: =Alumnos!B6 -> Alumno 5 | O30: =IF(OR($B30=$C30,$B30=$D30,$B30=$E30,$B30=$F30,$B30=$G30),"OK","FALTA") -> FALTA | P30: =IF(OR($H30=$C30,$H30=$D30,$H30=$E30,$H30=$F30,$H30=$G30),"OK","ERROR") -> OK | Q30: =INDEX(Calendario!$B$5:$B$16,MATCH($A30,Calendario!$A$5:$A$16,0)) -> 46300 | R30: =INDEX(Calendario!$C$5:$C$16,MATCH($A30,Calendario!$A$5:$A$16,0)) -> 46313 | S30: =TEXT(Q30,"DD/MM/YYYY")&" - "&TEXT(Q30+1,"DD/MM/YYYY") -> 05/10/YYYY - 06/10/YYYY
A31: 2 | B31: =Alumnos!B7 -> Alumno 6 | O31: =IF(OR($B31=$C31,$B31=$D31,$B31=$E31,$B31=$F31,$B31=$G31),"OK","FALTA") -> FALTA | P31: =IF(OR($H31=$C31,$H31=$D31,$H31=$E31,$H31=$F31,$H31=$G31),"OK","ERROR") -> OK | Q31: =INDEX(Calendario!$B$5:$B$16,MATCH($A31,Calendario!$A$5:$A$16,0)) -> 46300 | R31: =INDEX(Calendario!$C$5:$C$16,MATCH($A31,Calendario!$A$5:$A$16,0)) -> 46313 | S31: =TEXT(Q31,"DD/MM/YYYY")&" - "&TEXT(Q31+1,"DD/MM/YYYY") -> 05/10/YYYY - 06/10/YYYY
A32: 2 | B32: =Alumnos!B8 -> Alumno 7 | O32: =IF(OR($B32=$C32,$B32=$D32,$B32=$E32,$B32=$F32,$B32=$G32),"OK","FALTA") -> FALTA | P32: =IF(OR($H32=$C32,$H32=$D32,$H32=$E32,$H32=$F32,$H32=$G32),"OK","ERROR") -> OK | Q32: =INDEX(Calendario!$B$5:$B$16,MATCH($A32,Calendario!$A$5:$A$16,0)) -> 46300 | R32: =INDEX(Calendario!$C$5:$C$16,MATCH($A32,Calendario!$A$5:$A$16,0)) -> 46313 | S32: =TEXT(Q32,"DD/MM/YYYY")&" - "&TEXT(Q32+1,"DD/MM/YYYY") -> 05/10/YYYY - 06/10/YYYY
A33: 2 | B33: =Alumnos!B9 -> Alumno 8 | O33: =IF(OR($B33=$C33,$B33=$D33,$B33=$E33,$B33=$F33,$B33=$G33),"OK","FALTA") -> FALTA | P33: =IF(OR($H33=$C33,$H33=$D33,$H33=$E33,$H33=$F33,$H33=$G33),"OK","ERROR") -> OK | Q33: =INDEX(Calendario!$B$5:$B$16,MATCH($A33,Calendario!$A$5:$A$16,0)) -> 46300 | R33: =INDEX(Calendario!$C$5:$C$16,MATCH($A33,Calendario!$A$5:$A$16,0)) -> 46313 | S33: =TEXT(Q33,"DD/MM/YYYY")&" - "&TEXT(Q33+1,"DD/MM/YYYY") -> 05/10/YYYY - 06/10/YYYY
A34: 2 | B34: =Alumnos!B10 -> Alumno 9 | O34: =IF(OR($B34=$C34,$B34=$D34,$B34=$E34,$B34=$F34,$B34=$G34),"OK","FALTA") -> FALTA | P34: =IF(OR($H34=$C34,$H34=$D34,$H34=$E34,$H34=$F34,$H34=$G34),"OK","ERROR") -> OK | Q34: =INDEX(Calendario!$B$5:$B$16,MATCH($A34,Calendario!$A$5:$A$16,0)) -> 46300 | R34: =INDEX(Calendario!$C$5:$C$16,MATCH($A34,Calendario!$A$5:$A$16,0)) -> 46313 | S34: =TEXT(Q34,"DD/MM/YYYY")&" - "&TEXT(Q34+1,"DD/MM/YYYY") -> 05/10/YYYY - 06/10/YYYY
A35: 2 | B35: =Alumnos!B11 -> Alumno 10 | O35: =IF(OR($B35=$C35,$B35=$D35,$B35=$E35,$B35=$F35,$B35=$G35),"OK","FALTA") -> FALTA | P35: =IF(OR($H35=$C35,$H35=$D35,$H35=$E35,$H35=$F35,$H35=$G35),"OK","ERROR") -> OK | Q35: =INDEX(Calendario!$B$5:$B$16,MATCH($A35,Calendario!$A$5:$A$16,0)) -> 46300 | R35: =INDEX(Calendario!$C$5:$C$16,MATCH($A35,Calendario!$A$5:$A$16,0)) -> 46313 | S35: =TEXT(Q35,"DD/MM/YYYY")&" - "&TEXT(Q35+1,"DD/MM/YYYY") -> 05/10/YYYY - 06/10/YYYY
A36: 2 | B36: =Alumnos!B12 -> Alumno 11 | O36: =IF(OR($B36=$C36,$B36=$D36,$B36=$E36,$B36=$F36,$B36=$G36),"OK","FALTA") -> FALTA | P36: =IF(OR($H36=$C36,$H36=$D36,$H36=$E36,$H36=$F36,$H36=$G36),"OK","ERROR") -> OK | Q36: =INDEX(Calendario!$B$5:$B$16,MATCH($A36,Calendario!$A$5:$A$16,0)) -> 46300 | R36: =INDEX(Calendario!$C$5:$C$16,MATCH($A36,Calendario!$A$5:$A$16,0)) -> 46313 | S36: =TEXT(Q36,"DD/MM/YYYY")&" - "&TEXT(Q36+1,"DD/MM/YYYY") -> 05/10/YYYY - 06/10/YYYY
A37: 2 | B37: =Alumnos!B13 -> Alumno 12 | O37: =IF(OR($B37=$C37,$B37=$D37,$B37=$E37,$B37=$F37,$B37=$G37),"OK","FALTA") -> FALTA | P37: =IF(OR($H37=$C37,$H37=$D37,$H37=$E37,$H37=$F37,$H37=$G37),"OK","ERROR") -> OK | Q37: =INDEX(Calendario!$B$5:$B$16,MATCH($A37,Calendario!$A$5:$A$16,0)) -> 46300 | R37: =INDEX(Calendario!$C$5:$C$16,MATCH($A37,Calendario!$A$5:$A$16,0)) -> 46313 | S37: =TEXT(Q37,"DD/MM/YYYY")&" - "&TEXT(Q37+1,"DD/MM/YYYY") -> 05/10/YYYY - 06/10/YYYY
... A49: 2 | B49: =Alumnos!B25 -> Alumno 24 | O49: =IF(OR($B49=$C49,$B49=$D49,$B49=$E49,$B49=$F49,$B49=$G49),"OK","FALTA") -> FALTA | P49: =IF(OR($H49=$C49,$H49=$D49,$H49=$E49,$H49=$F49,$H49=$G49),"OK","ERROR") -> OK | Q49: =INDEX(Calendario!$B$5:$B$16,MATCH($A49,Calendario!$A$5:$A$16,0)) -> 46300 | R49: =INDEX(Calendario!$C$5:$C$16,MATCH($A49,Calendario!$A$5:$A$16,0)) -> 46313 | S49: =TEXT(Q49,"DD/MM/YYYY")&" - "&TEXT(Q49+1,"DD/MM/YYYY") -> 05/10/YYYY - 06/10/YYYY
A50: 3 | B50: =Alumnos!B2 -> Alumno 1 | O50: =IF(OR($B50=$C50,$B50=$D50,$B50=$E50,$B50=$F50,$B50=$G50),"OK","FALTA") -> FALTA | P50: =IF(OR($H50=$C50,$H50=$D50,$H50=$E50,$H50=$F50,$H50=$G50),"OK","ERROR") -> OK | Q50: =INDEX(Calendario!$B$5:$B$16,MATCH($A50,Calendario!$A$5:$A$16,0)) -> 46314 | R50: =INDEX(Calendario!$C$5:$C$16,MATCH($A50,Calendario!$A$5:$A$16,0)) -> 46327 | S50: =TEXT(Q50,"DD/MM/YYYY")&" - "&TEXT(Q50+1,"DD/MM/YYYY") -> 19/10/YYYY - 20/10/YYYY
A51: 3 | B51: =Alumnos!B3 -> Alumno 2 | O51: =IF(OR($B51=$C51,$B51=$D51,$B51=$E51,$B51=$F51,$B51=$G51),"OK","FALTA") -> FALTA | P51: =IF(OR($H51=$C51,$H51=$D51,$H51=$E51,$H51=$F51,$H51=$G51),"OK","ERROR") -> OK | Q51: =INDEX(Calendario!$B$5:$B$16,MATCH($A51,Calendario!$A$5:$A$16,0)) -> 46314 | R51: =INDEX(Calendario!$C$5:$C$16,MATCH($A51,Calendario!$A$5:$A$16,0)) -> 46327 | S51: =TEXT(Q51,"DD/MM/YYYY")&" - "&TEXT(Q51+1,"DD/MM/YYYY") -> 19/10/YYYY - 20/10/YYYY
A52: 3 | B52: =Alumnos!B4 -> Alumno 3 | O52: =IF(OR($B52=$C52,$B52=$D52,$B52=$E52,$B52=$F52,$B52=$G52),"OK","FALTA") -> FALTA | P52: =IF(OR($H52=$C52,$H52=$D52,$H52=$E52,$H52=$F52,$H52=$G52),"OK","ERROR") -> OK | Q52: =INDEX(Calendario!$B$5:$B$16,MATCH($A52,Calendario!$A$5:$A$16,0)) -> 46314 | R52: =INDEX(Calendario!$C$5:$C$16,MATCH($A52,Calendario!$A$5:$A$16,0)) -> 46327 | S52: =TEXT(Q52,"DD/MM/YYYY")&" - "&TEXT(Q52+1,"DD/MM/YYYY") -> 19/10/YYYY - 20/10/YYYY
A53: 3 | B53: =Alumnos!B5 -> Alumno 4 | O53: =IF(OR($B53=$C53,$B53=$D53,$B53=$E53,$B53=$F53,$B53=$G53),"OK","FALTA") -> FALTA | P53: =IF(OR($H53=$C53,$H53=$D53,$H53=$E53,$H53=$F53,$H53=$G53),"OK","ERROR") -> OK | Q53: =INDEX(Calendario!$B$5:$B$16,MATCH($A53,Calendario!$A$5:$A$16,0)) -> 46314 | R53: =INDEX(Calendario!$C$5:$C$16,MATCH($A53,Calendario!$A$5:$A$16,0)) -> 46327 | S53: =TEXT(Q53,"DD/MM/YYYY")&" - "&TEXT(Q53+1,"DD/MM/YYYY") -> 19/10/YYYY - 20/10/YYYY
A54: 3 | B54: =Alumnos!B6 -> Alumno 5 | O54: =IF(OR($B54=$C54,$B54=$D54,$B54=$E54,$B54=$F54,$B54=$G54),"OK","FALTA") -> FALTA | P54: =IF(OR($H54=$C54,$H54=$D54,$H54=$E54,$H54=$F54,$H54=$G54),"OK","ERROR") -> OK | Q54: =INDEX(Calendario!$B$5:$B$16,MATCH($A54,Calendario!$A$5:$A$16,0)) -> 46314 | R54: =INDEX(Calendario!$C$5:$C$16,MATCH($A54,Calendario!$A$5:$A$16,0)) -> 46327 | S54: =TEXT(Q54,"DD/MM/YYYY")&" - "&TEXT(Q54+1,"DD/MM/YYYY") -> 19/10/YYYY - 20/10/YYYY
A55: 3 | B55: =Alumnos!B7 -> Alumno 6 | O55: =IF(OR($B55=$C55,$B55=$D55,$B55=$E55,$B55=$F55,$B55=$G55),"OK","FALTA") -> FALTA | P55: =IF(OR($H55=$C55,$H55=$D55,$H55=$E55,$H55=$F55,$H55=$G55),"OK","ERROR") -> OK | Q55: =INDEX(Calendario!$B$5:$B$16,MATCH($A55,Calendario!$A$5:$A$16,0)) -> 46314 | R55: =INDEX(Calendario!$C$5:$C$16,MATCH($A55,Calendario!$A$5:$A$16,0)) -> 46327 | S55: =TEXT(Q55,"DD/MM/YYYY")&" - "&TEXT(Q55+1,"DD/MM/YYYY") -> 19/10/YYYY - 20/10/YYYY
A56: 3 | B56: =Alumnos!B8 -> Alumno 7 | O56: =IF(OR($B56=$C56,$B56=$D56,$B56=$E56,$B56=$F56,$B56=$G56),"OK","FALTA") -> FALTA | P56: =IF(OR($H56=$C56,$H56=$D56,$H56=$E56,$H56=$F56,$H56=$G56),"OK","ERROR") -> OK | Q56: =INDEX(Calendario!$B$5:$B$16,MATCH($A56,Calendario!$A$5:$A$16,0)) -> 46314 | R56: =INDEX(Calendario!$C$5:$C$16,MATCH($A56,Calendario!$A$5:$A$16,0)) -> 46327 | S56: =TEXT(Q56,"DD/MM/YYYY")&" - "&TEXT(Q56+1,"DD/MM/YYYY") -> 19/10/YYYY - 20/10/YYYY
A57: 3 | B57: =Alumnos!B9 -> Alumno 8 | O57: =IF(OR($B57=$C57,$B57=$D57,$B57=$E57,$B57=$F57,$B57=$G57),"OK","FALTA") -> FALTA | P57: =IF(OR($H57=$C57,$H57=$D57,$H57=$E57,$H57=$F57,$H57=$G57),"OK","ERROR") -> OK | Q57: =INDEX(Calendario!$B$5:$B$16,MATCH($A57,Calendario!$A$5:$A$16,0)) -> 46314 | R57: =INDEX(Calendario!$C$5:$C$16,MATCH($A57,Calendario!$A$5:$A$16,0)) -> 46327 | S57: =TEXT(Q57,"DD/MM/YYYY")&" - "&TEXT(Q57+1,"DD/MM/YYYY") -> 19/10/YYYY - 20/10/YYYY
A58: 3 | B58: =Alumnos!B10 -> Alumno 9 | O58: =IF(OR($B58=$C58,$B58=$D58,$B58=$E58,$B58=$F58,$B58=$G58),"OK","FALTA") -> FALTA | P58: =IF(OR($H58=$C58,$H58=$D58,$H58=$E58,$H58=$F58,$H58=$G58),"OK","ERROR") -> OK | Q58: =INDEX(Calendario!$B$5:$B$16,MATCH($A58,Calendario!$A$5:$A$16,0)) -> 46314 | R58: =INDEX(Calendario!$C$5:$C$16,MATCH($A58,Calendario!$A$5:$A$16,0)) -> 46327 | S58: =TEXT(Q58,"DD/MM/YYYY")&" - "&TEXT(Q58+1,"DD/MM/YYYY") -> 19/10/YYYY - 20/10/YYYY
A59: 3 | B59: =Alumnos!B11 -> Alumno 10 | O59: =IF(OR($B59=$C59,$B59=$D59,$B59=$E59,$B59=$F59,$B59=$G59),"OK","FALTA") -> FALTA | P59: =IF(OR($H59=$C59,$H59=$D59,$H59=$E59,$H59=$F59,$H59=$G59),"OK","ERROR") -> OK | Q59: =INDEX(Calendario!$B$5:$B$16,MATCH($A59,Calendario!$A$5:$A$16,0)) -> 46314 | R59: =INDEX(Calendario!$C$5:$C$16,MATCH($A59,Calendario!$A$5:$A$16,0)) -> 46327 | S59: =TEXT(Q59,"DD/MM/YYYY")&" - "&TEXT(Q59+1,"DD/MM/YYYY") -> 19/10/YYYY - 20/10/YYYY
A60: 3 | B60: =Alumnos!B12 -> Alumno 11 | O60: =IF(OR($B60=$C60,$B60=$D60,$B60=$E60,$B60=$F60,$B60=$G60),"OK","FALTA") -> FALTA | P60: =IF(OR($H60=$C60,$H60=$D60,$H60=$E60,$H60=$F60,$H60=$G60),"OK","ERROR") -> OK | Q60: =INDEX(Calendario!$B$5:$B$16,MATCH($A60,Calendario!$A$5:$A$16,0)) -> 46314 | R60: =INDEX(Calendario!$C$5:$C$16,MATCH($A60,Calendario!$A$5:$A$16,0)) -> 46327 | S60: =TEXT(Q60,"DD/MM/YYYY")&" - "&TEXT(Q60+1,"DD/MM/YYYY") -> 19/10/YYYY - 20/10/YYYY
A61: 3 | B61: =Alumnos!B13 -> Alumno 12 | O61: =IF(OR($B61=$C61,$B61=$D61,$B61=$E61,$B61=$F61,$B61=$G61),"OK","FALTA") -> FALTA | P61: =IF(OR($H61=$C61,$H61=$D61,$H61=$E61,$H61=$F61,$H61=$G61),"OK","ERROR") -> OK | Q61: =INDEX(Calendario!$B$5:$B$16,MATCH($A61,Calendario!$A$5:$A$16,0)) -> 46314 | R61: =INDEX(Calendario!$C$5:$C$16,MATCH($A61,Calendario!$A$5:$A$16,0)) -> 46327 | S61: =TEXT(Q61,"DD/MM/YYYY")&" - "&TEXT(Q61+1,"DD/MM/YYYY") -> 19/10/YYYY - 20/10/YYYY
...

Sheet Puntos_Jornada
A1: Alumno | B1: 1 | C1: 2 | D1: 3 | E1: 4 | F1: 5 | G1: 6 | H1: 7 | I1: 8 | J1: 9 | K1: 10 | L1: 11 | M1: 12 | N1: Total temporada
A2: =Alumnos!B2 -> Alumno 1 | B2: =SUMIFS(Eventos!$E$2:$E$401,Eventos!$C$2:$C$401,$A2,Eventos!$B$2:$B$401,B$1) -> 8 | C2: =SUMIFS(Eventos!$E$2:$E$401,Eventos!$C$2:$C$401,$A2,Eventos!$B$2:$B$401,C$1) -> 0 | D2: =SUMIFS(Eventos!$E$2:$E$401,Eventos!$C$2:$C$401,$A2,Eventos!$B$2:$B$401,D$1) -> 0 | E2: =SUMIFS(Eventos!$E$2:$E$401,Eventos!$C$2:$C$401,$A2,Eventos!$B$2:$B$401,E$1) -> 0 | F2: =SUMIFS(Eventos!$E$2:$E$401,Eventos!$C$2:$C$401,$A2,Eventos!$B$2:$B$401,F$1) -> 0 | G2: =SUMIFS(Eventos!$E$2:$E$401,Eventos!$C$2:$C$401,$A2,Eventos!$B$2:$B$401,G$1) -> 0 | H2: =SUMIFS(Eventos!$E$2:$E$401,Eventos!$C$2:$C$401,$A2,Eventos!$B$2:$B$401,H$1) -> 0 | I2: =SUMIFS(Eventos!$E$2:$E$401,Eventos!$C$2:$C$401,$A2,Eventos!$B$2:$B$401,I$1) -> 0 | ... M2: =SUMIFS(Eventos!$E$2:$E$401,Eventos!$C$2:$C$401,$A2,Eventos!$B$2:$B$401,M$1) -> 0 | N2: =SUM(B2:M2) -> 8
A3: =Alumnos!B3 -> Alumno 2 | B3: =SUMIFS(Eventos!$E$2:$E$401,Eventos!$C$2:$C$401,$A3,Eventos!$B$2:$B$401,B$1) -> 0 | C3: =SUMIFS(Eventos!$E$2:$E$401,Eventos!$C$2:$C$401,$A3,Eventos!$B$2:$B$401,C$1) -> 0 | D3: =SUMIFS(Eventos!$E$2:$E$401,Eventos!$C$2:$C$401,$A3,Eventos!$B$2:$B$401,D$1) -> 0 | E3: =SUMIFS(Eventos!$E$2:$E$401,Eventos!$C$2:$C$401,$A3,Eventos!$B$2:$B$401,E$1) -> 0 | F3: =SUMIFS(Eventos!$E$2:$E$401,Eventos!$C$2:$C$401,$A3,Eventos!$B$2:$B$401,F$1) -> 0 | G3: =SUMIFS(Eventos!$E$2:$E$401,Eventos!$C$2:$C$401,$A3,Eventos!$B$2:$B$401,G$1) -> 0 | H3: =SUMIFS(Eventos!$E$2:$E$401,Eventos!$C$2:$C$401,$A3,Eventos!$B$2:$B$401,H$1) -> 0 | I3: =SUMIFS(Eventos!$E$2:$E$401,Eventos!$C$2:$C$401,$A3,Eventos!$B$2:$B$401,I$1) -> 0 | ... M3: =SUMIFS(Eventos!$E$2:$E$401,Eventos!$C$2:$C$401,$A3,Eventos!$B$2:$B$401,M$1) -> 0 | N3: =SUM(B3:M3) -> 0
A4: =Alumnos!B4 -> Alumno 3 | B4: =SUMIFS(Eventos!$E$2:$E$401,Eventos!$C$2:$C$401,$A4,Eventos!$B$2:$B$401,B$1) -> 0 | C4: =SUMIFS(Eventos!$E$2:$E$401,Eventos!$C$2:$C$401,$A4,Eventos!$B$2:$B$401,C$1) -> 0 | D4: =SUMIFS(Eventos!$E$2:$E$401,Eventos!$C$2:$C$401,$A4,Eventos!$B$2:$B$401,D$1) -> 0 | E4: =SUMIFS(Eventos!$E$2:$E$401,Eventos!$C$2:$C$401,$A4,Eventos!$B$2:$B$401,E$1) -> 0 | F4: =SUMIFS(Eventos!$E$2:$E$401,Eventos!$C$2:$C$401,$A4,Eventos!$B$2:$B$401,F$1) -> 0 | G4: =SUMIFS(Eventos!$E$2:$E$401,Eventos!$C$2:$C$401,$A4,Eventos!$B$2:$B$401,G$1) -> 0 | H4: =SUMIFS(Eventos!$E$2:$E$401,Eventos!$C$2:$C$401,$A4,Eventos!$B$2:$B$401,H$1) -> 0 | I4: =SUMIFS(Eventos!$E$2:$E$401,Eventos!$C$2:$C$401,$A4,Eventos!$B$2:$B$401,I$1) -> 0 | ... M4: =SUMIFS(Eventos!$E$2:$E$401,Eventos!$C$2:$C$401,$A4,Eventos!$B$2:$B$401,M$1) -> 0 | N4: =SUM(B4:M4) -> 0
A5: =Alumnos!B5 -> Alumno 4 | B5: =SUMIFS(Eventos!$E$2:$E$401,Eventos!$C$2:$C$401,$A5,Eventos!$B$2:$B$401,B$1) -> 0 | C5: =SUMIFS(Eventos!$E$2:$E$401,Eventos!$C$2:$C$401,$A5,Eventos!$B$2:$B$401,C$1) -> 0 | D5: =SUMIFS(Eventos!$E$2:$E$401,Eventos!$C$2:$C$401,$A5,Eventos!$B$2:$B$401,D$1) -> 0 | E5: =SUMIFS(Eventos!$E$2:$E$401,Eventos!$C$2:$C$401,$A5,Eventos!$B$2:$B$401,E$1) -> 0 | F5: =SUMIFS(Eventos!$E$2:$E$401,Eventos!$C$2:$C$401,$A5,Eventos!$B$2:$B$401,F$1) -> 0 | G5: =SUMIFS(Eventos!$E$2:$E$401,Eventos!$C$2:$C$401,$A5,Eventos!$B$2:$B$401,G$1) -> 0 | H5: =SUMIFS(Eventos!$E$2:$E$401,Eventos!$C$2:$C$401,$A5,Eventos!$B$2:$B$401,H$1) -> 0 | I5: =SUMIFS(Eventos!$E$2:$E$401,Eventos!$C$2:$C$401,$A5,Eventos!$B$2:$B$401,I$1) -> 0 | ... M5: =SUMIFS(Eventos!$E$2:$E$401,Eventos!$C$2:$C$401,$A5,Eventos!$B$2:$B$401,M$1) -> 0 | N5: =SUM(B5:M5) -> 0
A6: =Alumnos!B6 -> Alumno 5 | B6: =SUMIFS(Eventos!$E$2:$E$401,Eventos!$C$2:$C$401,$A6,Eventos!$B$2:$B$401,B$1) -> 0 | C6: =SUMIFS(Eventos!$E$2:$E$401,Eventos!$C$2:$C$401,$A6,Eventos!$B$2:$B$401,C$1) -> 0 | D6: =SUMIFS(Eventos!$E$2:$E$401,Eventos!$C$2:$C$401,$A6,Eventos!$B$2:$B$401,D$1) -> 0 | E6: =SUMIFS(Eventos!$E$2:$E$401,Eventos!$C$2:$C$401,$A6,Eventos!$B$2:$B$401,E$1) -> 0 | F6: =SUMIFS(Eventos!$E$2:$E$401,Eventos!$C$2:$C$401,$A6,Eventos!$B$2:$B$401,F$1) -> 0 | G6: =SUMIFS(Eventos!$E$2:$E$401,Eventos!$C$2:$C$401,$A6,Eventos!$B$2:$B$401,G$1) -> 0 | H6: =SUMIFS(Eventos!$E$2:$E$401,Eventos!$C$2:$C$401,$A6,Eventos!$B$2:$B$401,H$1) -> 0 | I6: =SUMIFS(Eventos!$E$2:$E$401,Eventos!$C$2:$C$401,$A6,Eventos!$B$2:$B$401,I$1) -> 0 | ... M6: =SUMIFS(Eventos!$E$2:$E$401,Eventos!$C$2:$C$401,$A6,Eventos!$B$2:$B$401,M$1) -> 0 | N6: =SUM(B6:M6) -> 0
A7: =Alumnos!B7 -> Alumno 6 | B7: =SUMIFS(Eventos!$E$2:$E$401,Eventos!$C$2:$C$401,$A7,Eventos!$B$2:$B$401,B$1) -> 0 | C7: =SUMIFS(Eventos!$E$2:$E$401,Eventos!$C$2:$C$401,$A7,Eventos!$B$2:$B$401,C$1) -> 0 | D7: =SUMIFS(Eventos!$E$2:$E$401,Eventos!$C$2:$C$401,$A7,Eventos!$B$2:$B$401,D$1) -> 0 | E7: =SUMIFS(Eventos!$E$2:$E$401,Eventos!$C$2:$C$401,$A7,Eventos!$B$2:$B$401,E$1) -> 0 | F7: =SUMIFS(Eventos!$E$2:$E$401,Eventos!$C$2:$C$401,$A7,Eventos!$B$2:$B$401,F$1) -> 0 | G7: =SUMIFS(Eventos!$E$2:$E$401,Eventos!$C$2:$C$401,$A7,Eventos!$B$2:$B$401,G$1) -> 0 | H7: =SUMIFS(Eventos!$E$2:$E$401,Eventos!$C$2:$C$401,$A7,Eventos!$B$2:$B$401,H$1) -> 0 | I7: =SUMIFS(Eventos!$E$2:$E$401,Eventos!$C$2:$C$401,$A7,Eventos!$B$2:$B$401,I$1) -> 0 | ... M7: =SUMIFS(Eventos!$E$2:$E$401,Eventos!$C$2:$C$401,$A7,Eventos!$B$2:$B$401,M$1) -> 0 | N7: =SUM(B7:M7) -> 0
A8: =Alumnos!B8 -> Alumno 7 | B8: =SUMIFS(Eventos!$E$2:$E$401,Eventos!$C$2:$C$401,$A8,Eventos!$B$2:$B$401,B$1) -> 0 | C8: =SUMIFS(Eventos!$E$2:$E$401,Eventos!$C$2:$C$401,$A8,Eventos!$B$2:$B$401,C$1) -> 0 | D8: =SUMIFS(Eventos!$E$2:$E$401,Eventos!$C$2:$C$401,$A8,Eventos!$B$2:$B$401,D$1) -> 0 | E8: =SUMIFS(Eventos!$E$2:$E$401,Eventos!$C$2:$C$401,$A8,Eventos!$B$2:$B$401,E$1) -> 0 | F8: =SUMIFS(Eventos!$E$2:$E$401,Eventos!$C$2:$C$401,$A8,Eventos!$B$2:$B$401,F$1) -> 0 | G8: =SUMIFS(Eventos!$E$2:$E$401,Eventos!$C$2:$C$401,$A8,Eventos!$B$2:$B$401,G$1) -> 0 | H8: =SUMIFS(Eventos!$E$2:$E$401,Eventos!$C$2:$C$401,$A8,Eventos!$B$2:$B$401,H$1) -> 0 | I8: =SUMIFS(Eventos!$E$2:$E$401,Eventos!$C$2:$C$401,$A8,Eventos!$B$2:$B$401,I$1) -> 0 | ... M8: =SUMIFS(Eventos!$E$2:$E$401,Eventos!$C$2:$C$401,$A8,Eventos!$B$2:$B$401,M$1) -> 0 | N8: =SUM(B8:M8) -> 0
A9: =Alumnos!B9 -> Alumno 8 | B9: =SUMIFS(Eventos!$E$2:$E$401,Eventos!$C$2:$C$401,$A9,Eventos!$B$2:$B$401,B$1) -> 0 | C9: =SUMIFS(Eventos!$E$2:$E$401,Eventos!$C$2:$C$401,$A9,Eventos!$B$2:$B$401,C$1) -> 0 | D9: =SUMIFS(Eventos!$E$2:$E$401,Eventos!$C$2:$C$401,$A9,Eventos!$B$2:$B$401,D$1) -> 0 | E9: =SUMIFS(Eventos!$E$2:$E$401,Eventos!$C$2:$C$401,$A9,Eventos!$B$2:$B$401,E$1) -> 0 | F9: =SUMIFS(Eventos!$E$2:$E$401,Eventos!$C$2:$C$401,$A9,Eventos!$B$2:$B$401,F$1) -> 0 | G9: =SUMIFS(Eventos!$E$2:$E$401,Eventos!$C$2:$C$401,$A9,Eventos!$B$2:$B$401,G$1) -> 0 | H9: =SUMIFS(Eventos!$E$2:$E$401,Eventos!$C$2:$C$401,$A9,Eventos!$B$2:$B$401,H$1) -> 0 | I9: =SUMIFS(Eventos!$E$2:$E$401,Eventos!$C$2:$C$401,$A9,Eventos!$B$2:$B$401,I$1) -> 0 | ... M9: =SUMIFS(Eventos!$E$2:$E$401,Eventos!$C$2:$C$401,$A9,Eventos!$B$2:$B$401,M$1) -> 0 | N9: =SUM(B9:M9) -> 0
A10: =Alumnos!B10 -> Alumno 9 | B10: =SUMIFS(Eventos!$E$2:$E$401,Eventos!$C$2:$C$401,$A10,Eventos!$B$2:$B$401,B$1) -> 0 | C10: =SUMIFS(Eventos!$E$2:$E$401,Eventos!$C$2:$C$401,$A10,Eventos!$B$2:$B$401,C$1) -> 0 | D10: =SUMIFS(Eventos!$E$2:$E$401,Eventos!$C$2:$C$401,$A10,Eventos!$B$2:$B$401,D$1) -> 0 | E10: =SUMIFS(Eventos!$E$2:$E$401,Eventos!$C$2:$C$401,$A10,Eventos!$B$2:$B$401,E$1) -> 0 | F10: =SUMIFS(Eventos!$E$2:$E$401,Eventos!$C$2:$C$401,$A10,Eventos!$B$2:$B$401,F$1) -> 0 | G10: =SUMIFS(Eventos!$E$2:$E$401,Eventos!$C$2:$C$401,$A10,Eventos!$B$2:$B$401,G$1) -> 0 | H10: =SUMIFS(Eventos!$E$2:$E$401,Eventos!$C$2:$C$401,$A10,Eventos!$B$2:$B$401,H$1) -> 0 | I10: =SUMIFS(Eventos!$E$2:$E$401,Eventos!$C$2:$C$401,$A10,Eventos!$B$2:$B$401,I$1) -> 0 | ... M10: =SUMIFS(Eventos!$E$2:$E$401,Eventos!$C$2:$C$401,$A10,Eventos!$B$2:$B$401,M$1) -> 0 | N10: =SUM(B10:M10) -> 0
A11: =Alumnos!B11 -> Alumno 10 | B11: =SUMIFS(Eventos!$E$2:$E$401,Eventos!$C$2:$C$401,$A11,Eventos!$B$2:$B$401,B$1) -> 0 | C11: =SUMIFS(Eventos!$E$2:$E$401,Eventos!$C$2:$C$401,$A11,Eventos!$B$2:$B$401,C$1) -> 0 | D11: =SUMIFS(Eventos!$E$2:$E$401,Eventos!$C$2:$C$401,$A11,Eventos!$B$2:$B$401,D$1) -> 0 | E11: =SUMIFS(Eventos!$E$2:$E$401,Eventos!$C$2:$C$401,$A11,Eventos!$B$2:$B$401,E$1) -> 0 | F11: =SUMIFS(Eventos!$E$2:$E$401,Eventos!$C$2:$C$401,$A11,Eventos!$B$2:$B$401,F$1) -> 0 | G11: =SUMIFS(Eventos!$E$2:$E$401,Eventos!$C$2:$C$401,$A11,Eventos!$B$2:$B$401,G$1) -> 0 | H11: =SUMIFS(Eventos!$E$2:$E$401,Eventos!$C$2:$C$401,$A11,Eventos!$B$2:$B$401,H$1) -> 0 | I11: =SUMIFS(Eventos!$E$2:$E$401,Eventos!$C$2:$C$401,$A11,Eventos!$B$2:$B$401,I$1) -> 0 | ... M11: =SUMIFS(Eventos!$E$2:$E$401,Eventos!$C$2:$C$401,$A11,Eventos!$B$2:$B$401,M$1) -> 0 | N11: =SUM(B11:M11) -> 0
A12: =Alumnos!B12 -> Alumno 11 | B12: =SUMIFS(Eventos!$E$2:$E$401,Eventos!$C$2:$C$401,$A12,Eventos!$B$2:$B$401,B$1) -> 0 | C12: =SUMIFS(Eventos!$E$2:$E$401,Eventos!$C$2:$C$401,$A12,Eventos!$B$2:$B$401,C$1) -> 0 | D12: =SUMIFS(Eventos!$E$2:$E$401,Eventos!$C$2:$C$401,$A12,Eventos!$B$2:$B$401,D$1) -> 0 | E12: =SUMIFS(Eventos!$E$2:$E$401,Eventos!$C$2:$C$401,$A12,Eventos!$B$2:$B$401,E$1) -> 0 | F12: =SUMIFS(Eventos!$E$2:$E$401,Eventos!$C$2:$C$401,$A12,Eventos!$B$2:$B$401,F$1) -> 0 | G12: =SUMIFS(Eventos!$E$2:$E$401,Eventos!$C$2:$C$401,$A12,Eventos!$B$2:$B$401,G$1) -> 0 | H12: =SUMIFS(Eventos!$E$2:$E$401,Eventos!$C$2:$C$401,$A12,Eventos!$B$2:$B$401,H$1) -> 0 | I12: =SUMIFS(Eventos!$E$2:$E$401,Eventos!$C$2:$C$401,$A12,Eventos!$B$2:$B$401,I$1) -> 0 | ... M12: =SUMIFS(Eventos!$E$2:$E$401,Eventos!$C$2:$C$401,$A12,Eventos!$B$2:$B$401,M$1) -> 0 | N12: =SUM(B12:M12) -> 0
A13: =Alumnos!B13 -> Alumno 12 | B13: =SUMIFS(Eventos!$E$2:$E$401,Eventos!$C$2:$C$401,$A13,Eventos!$B$2:$B$401,B$1) -> 0 | C13: =SUMIFS(Eventos!$E$2:$E$401,Eventos!$C$2:$C$401,$A13,Eventos!$B$2:$B$401,C$1) -> 0 | D13: =SUMIFS(Eventos!$E$2:$E$401,Eventos!$C$2:$C$401,$A13,Eventos!$B$2:$B$401,D$1) -> 0 | E13: =SUMIFS(Eventos!$E$2:$E$401,Eventos!$C$2:$C$401,$A13,Eventos!$B$2:$B$401,E$1) -> 0 | F13: =SUMIFS(Eventos!$E$2:$E$401,Eventos!$C$2:$C$401,$A13,Eventos!$B$2:$B$401,F$1) -> 0 | G13: =SUMIFS(Eventos!$E$2:$E$401,Eventos!$C$2:$C$401,$A13,Eventos!$B$2:$B$401,G$1) -> 0 | H13: =SUMIFS(Eventos!$E$2:$E$401,Eventos!$C$2:$C$401,$A13,Eventos!$B$2:$B$401,H$1) -> 0 | I13: =SUMIFS(Eventos!$E$2:$E$401,Eventos!$C$2:$C$401,$A13,Eventos!$B$2:$B$401,I$1) -> 0 | ... M13: =SUMIFS(Eventos!$E$2:$E$401,Eventos!$C$2:$C$401,$A13,Eventos!$B$2:$B$401,M$1) -> 0 | N13: =SUM(B13:M13) -> 0
... A25: =Alumnos!B25 -> Alumno 24 | B25: =SUMIFS(Eventos!$E$2:$E$401,Eventos!$C$2:$C$401,$A25,Eventos!$B$2:$B$401,B$1) -> 0 | C25: =SUMIFS(Eventos!$E$2:$E$401,Eventos!$C$2:$C$401,$A25,Eventos!$B$2:$B$401,C$1) -> 0 | D25: =SUMIFS(Eventos!$E$2:$E$401,Eventos!$C$2:$C$401,$A25,Eventos!$B$2:$B$401,D$1) -> 0 | E25: =SUMIFS(Eventos!$E$2:$E$401,Eventos!$C$2:$C$401,$A25,Eventos!$B$2:$B$401,E$1) -> 0 | F25: =SUMIFS(Eventos!$E$2:$E$401,Eventos!$C$2:$C$401,$A25,Eventos!$B$2:$B$401,F$1) -> 0 | G25: =SUMIFS(Eventos!$E$2:$E$401,Eventos!$C$2:$C$401,$A25,Eventos!$B$2:$B$401,G$1) -> 0 | H25: =SUMIFS(Eventos!$E$2:$E$401,Eventos!$C$2:$C$401,$A25,Eventos!$B$2:$B$401,H$1) -> 0 | I25: =SUMIFS(Eventos!$E$2:$E$401,Eventos!$C$2:$C$401,$A25,Eventos!$B$2:$B$401,I$1) -> 0 | ... M25: =SUMIFS(Eventos!$E$2:$E$401,Eventos!$C$2:$C$401,$A25,Eventos!$B$2:$B$401,M$1) -> 0 | N25: =SUM(B25:M25) -> 0

Sheet Clasificacion
A1: Jornada | B1: Manager | C1: Puntos Jugador 1 | D1: Puntos Jugador 2 | E1: Puntos Jugador 3 | F1: Puntos Jugador 4 | G1: Puntos Jugador 5 | H1: Puntos Capitan (bonus) | I1: Total jornada
A2: =Plantillas!A2 -> 1 | B2: =Plantillas!B2 -> Alumno 1 | C2: =IFERROR(INDEX(Puntos_Jornada!$B$2:$M$25,MATCH(Plantillas!C2,Puntos_Jornada!$A$2:$A$25,0),MATCH($A2,Puntos_Jornada!$B$1:$M$1,0)),0) -> 8 | D2: =IFERROR(INDEX(Puntos_Jornada!$B$2:$M$25,MATCH(Plantillas!D2,Puntos_Jornada!$A$2:$A$25,0),MATCH($A2,Puntos_Jornada!$B$1:$M$1,0)),0) -> 0 | E2: =IFERROR(INDEX(Puntos_Jornada!$B$2:$M$25,MATCH(Plantillas!E2,Puntos_Jornada!$A$2:$A$25,0),MATCH($A2,Puntos_Jornada!$B$1:$M$1,0)),0) -> 0 | F2: =IFERROR(INDEX(Puntos_Jornada!$B$2:$M$25,MATCH(Plantillas!F2,Puntos_Jornada!$A$2:$A$25,0),MATCH($A2,Puntos_Jornada!$B$1:$M$1,0)),0) -> 8 | G2: =IFERROR(INDEX(Puntos_Jornada!$B$2:$M$25,MATCH(Plantillas!G2,Puntos_Jornada!$A$2:$A$25,0),MATCH($A2,Puntos_Jornada!$B$1:$M$1,0)),0) -> 0 | H2: =IFERROR(INDEX(Puntos_Jornada!$B$2:$M$25,MATCH(Plantillas!H2,Puntos_Jornada!$A$2:$A$25,0),MATCH($A2,Puntos_Jornada!$B$1:$M$1,0)),0) -> 8 | I2: =SUM(C2:G2)+H2 -> 24
A3: =Plantillas!A3 -> 1 | B3: =Plantillas!B3 -> Alumno 2 | C3: =IFERROR(INDEX(Puntos_Jornada!$B$2:$M$25,MATCH(Plantillas!C3,Puntos_Jornada!$A$2:$A$25,0),MATCH($A3,Puntos_Jornada!$B$1:$M$1,0)),0) -> 0 | D3: =IFERROR(INDEX(Puntos_Jornada!$B$2:$M$25,MATCH(Plantillas!D3,Puntos_Jornada!$A$2:$A$25,0),MATCH($A3,Puntos_Jornada!$B$1:$M$1,0)),0) -> 0 | E3: =IFERROR(INDEX(Puntos_Jornada!$B$2:$M$25,MATCH(Plantillas!E3,Puntos_Jornada!$A$2:$A$25,0),MATCH($A3,Puntos_Jornada!$B$1:$M$1,0)),0) -> 0 | F3: =IFERROR(INDEX(Puntos_Jornada!$B$2:$M$25,MATCH(Plantillas!F3,Puntos_Jornada!$A$2:$A$25,0),MATCH($A3,Puntos_Jornada!$B$1:$M$1,0)),0) -> 0 | G3: =IFERROR(INDEX(Puntos_Jornada!$B$2:$M$25,MATCH(Plantillas!G3,Puntos_Jornada!$A$2:$A$25,0),MATCH($A3,Puntos_Jornada!$B$1:$M$1,0)),0) -> 0 | H3: =IFERROR(INDEX(Puntos_Jornada!$B$2:$M$25,MATCH(Plantillas!H3,Puntos_Jornada!$A$2:$A$25,0),MATCH($A3,Puntos_Jornada!$B$1:$M$1,0)),0) -> 0 | I3: =SUM(C3:G3)+H3 -> 0
A4: =Plantillas!A4 -> 1 | B4: =Plantillas!B4 -> Alumno 3 | C4: =IFERROR(INDEX(Puntos_Jornada!$B$2:$M$25,MATCH(Plantillas!C4,Puntos_Jornada!$A$2:$A$25,0),MATCH($A4,Puntos_Jornada!$B$1:$M$1,0)),0) -> 0 | D4: =IFERROR(INDEX(Puntos_Jornada!$B$2:$M$25,MATCH(Plantillas!D4,Puntos_Jornada!$A$2:$A$25,0),MATCH($A4,Puntos_Jornada!$B$1:$M$1,0)),0) -> 0 | E4: =IFERROR(INDEX(Puntos_Jornada!$B$2:$M$25,MATCH(Plantillas!E4,Puntos_Jornada!$A$2:$A$25,0),MATCH($A4,Puntos_Jornada!$B$1:$M$1,0)),0) -> 0 | F4: =IFERROR(INDEX(Puntos_Jornada!$B$2:$M$25,MATCH(Plantillas!F4,Puntos_Jornada!$A$2:$A$25,0),MATCH($A4,Puntos_Jornada!$B$1:$M$1,0)),0) -> 0 | G4: =IFERROR(INDEX(Puntos_Jornada!$B$2:$M$25,MATCH(Plantillas!G4,Puntos_Jornada!$A$2:$A$25,0),MATCH($A4,Puntos_Jornada!$B$1:$M$1,0)),0) -> 0 | H4: =IFERROR(INDEX(Puntos_Jornada!$B$2:$M$25,MATCH(Plantillas!H4,Puntos_Jornada!$A$2:$A$25,0),MATCH($A4,Puntos_Jornada!$B$1:$M$1,0)),0) -> 0 | I4: =SUM(C4:G4)+H4 -> 0
A5: =Plantillas!A5 -> 1 | B5: =Plantillas!B5 -> Alumno 4 | C5: =IFERROR(INDEX(Puntos_Jornada!$B$2:$M$25,MATCH(Plantillas!C5,Puntos_Jornada!$A$2:$A$25,0),MATCH($A5,Puntos_Jornada!$B$1:$M$1,0)),0) -> 0 | D5: =IFERROR(INDEX(Puntos_Jornada!$B$2:$M$25,MATCH(Plantillas!D5,Puntos_Jornada!$A$2:$A$25,0),MATCH($A5,Puntos_Jornada!$B$1:$M$1,0)),0) -> 0 | E5: =IFERROR(INDEX(Puntos_Jornada!$B$2:$M$25,MATCH(Plantillas!E5,Puntos_Jornada!$A$2:$A$25,0),MATCH($A5,Puntos_Jornada!$B$1:$M$1,0)),0) -> 0 | F5: =IFERROR(INDEX(Puntos_Jornada!$B$2:$M$25,MATCH(Plantillas!F5,Puntos_Jornada!$A$2:$A$25,0),MATCH($A5,Puntos_Jornada!$B$1:$M$1,0)),0) -> 0 | G5: =IFERROR(INDEX(Puntos_Jornada!$B$2:$M$25,MATCH(Plantillas!G5,Puntos_Jornada!$A$2:$A$25,0),MATCH($A5,Puntos_Jornada!$B$1:$M$1,0)),0) -> 0 | H5: =IFERROR(INDEX(Puntos_Jornada!$B$2:$M$25,MATCH(Plantillas!H5,Puntos_Jornada!$A$2:$A$25,0),MATCH($A5,Puntos_Jornada!$B$1:$M$1,0)),0) -> 0 | I5: =SUM(C5:G5)+H5 -> 0
A6: =Plantillas!A6 -> 1 | B6: =Plantillas!B6 -> Alumno 5 | C6: =IFERROR(INDEX(Puntos_Jornada!$B$2:$M$25,MATCH(Plantillas!C6,Puntos_Jornada!$A$2:$A$25,0),MATCH($A6,Puntos_Jornada!$B$1:$M$1,0)),0) -> 0 | D6: =IFERROR(INDEX(Puntos_Jornada!$B$2:$M$25,MATCH(Plantillas!D6,Puntos_Jornada!$A$2:$A$25,0),MATCH($A6,Puntos_Jornada!$B$1:$M$1,0)),0) -> 0 | E6: =IFERROR(INDEX(Puntos_Jornada!$B$2:$M$25,MATCH(Plantillas!E6,Puntos_Jornada!$A$2:$A$25,0),MATCH($A6,Puntos_Jornada!$B$1:$M$1,0)),0) -> 0 | F6: =IFERROR(INDEX(Puntos_Jornada!$B$2:$M$25,MATCH(Plantillas!F6,Puntos_Jornada!$A$2:$A$25,0),MATCH($A6,Puntos_Jornada!$B$1:$M$1,0)),0) -> 0 | G6: =IFERROR(INDEX(Puntos_Jornada!$B$2:$M$25,MATCH(Plantillas!G6,Puntos_Jornada!$A$2:$A$25,0),MATCH($A6,Puntos_Jornada!$B$1:$M$1,0)),0) -> 0 | H6: =IFERROR(INDEX(Puntos_Jornada!$B$2:$M$25,MATCH(Plantillas!H6,Puntos_Jornada!$A$2:$A$25,0),MATCH($A6,Puntos_Jornada!$B$1:$M$1,0)),0) -> 0 | I6: =SUM(C6:G6)+H6 -> 0
A7: =Plantillas!A7 -> 1 | B7: =Plantillas!B7 -> Alumno 6 | C7: =IFERROR(INDEX(Puntos_Jornada!$B$2:$M$25,MATCH(Plantillas!C7,Puntos_Jornada!$A$2:$A$25,0),MATCH($A7,Puntos_Jornada!$B$1:$M$1,0)),0) -> 0 | D7: =IFERROR(INDEX(Puntos_Jornada!$B$2:$M$25,MATCH(Plantillas!D7,Puntos_Jornada!$A$2:$A$25,0),MATCH($A7,Puntos_Jornada!$B$1:$M$1,0)),0) -> 0 | E7: =IFERROR(INDEX(Puntos_Jornada!$B$2:$M$25,MATCH(Plantillas!E7,Puntos_Jornada!$A$2:$A$25,0),MATCH($A7,Puntos_Jornada!$B$1:$M$1,0)),0) -> 0 | F7: =IFERROR(INDEX(Puntos_Jornada!$B$2:$M$25,MATCH(Plantillas!F7,Puntos_Jornada!$A$2:$A$25,0),MATCH($A7,Puntos_Jornada!$B$1:$M$1,0)),0) -> 0 | G7: =IFERROR(INDEX(Puntos_Jornada!$B$2:$M$25,MATCH(Plantillas!G7,Puntos_Jornada!$A$2:$A$25,0),MATCH($A7,Puntos_Jornada!$B$1:$M$1,0)),0) -> 0 | H7: =IFERROR(INDEX(Puntos_Jornada!$B$2:$M$25,MATCH(Plantillas!H7,Puntos_Jornada!$A$2:$A$25,0),MATCH($A7,Puntos_Jornada!$B$1:$M$1,0)),0) -> 0 | I7: =SUM(C7:G7)+H7 -> 0
A8: =Plantillas!A8 -> 1 | B8: =Plantillas!B8 -> Alumno 7 | C8: =IFERROR(INDEX(Puntos_Jornada!$B$2:$M$25,MATCH(Plantillas!C8,Puntos_Jornada!$A$2:$A$25,0),MATCH($A8,Puntos_Jornada!$B$1:$M$1,0)),0) -> 0 | D8: =IFERROR(INDEX(Puntos_Jornada!$B$2:$M$25,MATCH(Plantillas!D8,Puntos_Jornada!$A$2:$A$25,0),MATCH($A8,Puntos_Jornada!$B$1:$M$1,0)),0) -> 0 | E8: =IFERROR(INDEX(Puntos_Jornada!$B$2:$M$25,MATCH(Plantillas!E8,Puntos_Jornada!$A$2:$A$25,0),MATCH($A8,Puntos_Jornada!$B$1:$M$1,0)),0) -> 0 | F8: =IFERROR(INDEX(Puntos_Jornada!$B$2:$M$25,MATCH(Plantillas!F8,Puntos_Jornada!$A$2:$A$25,0),MATCH($A8,Puntos_Jornada!$B$1:$M$1,0)),0) -> 0 | G8: =IFERROR(INDEX(Puntos_Jornada!$B$2:$M$25,MATCH(Plantillas!G8,Puntos_Jornada!$A$2:$A$25,0),MATCH($A8,Puntos_Jornada!$B$1:$M$1,0)),0) -> 0 | H8: =IFERROR(INDEX(Puntos_Jornada!$B$2:$M$25,MATCH(Plantillas!H8,Puntos_Jornada!$A$2:$A$25,0),MATCH($A8,Puntos_Jornada!$B$1:$M$1,0)),0) -> 0 | I8: =SUM(C8:G8)+H8 -> 0
A9: =Plantillas!A9 -> 1 | B9: =Plantillas!B9 -> Alumno 8 | C9: =IFERROR(INDEX(Puntos_Jornada!$B$2:$M$25,MATCH(Plantillas!C9,Puntos_Jornada!$A$2:$A$25,0),MATCH($A9,Puntos_Jornada!$B$1:$M$1,0)),0) -> 0 | D9: =IFERROR(INDEX(Puntos_Jornada!$B$2:$M$25,MATCH(Plantillas!D9,Puntos_Jornada!$A$2:$A$25,0),MATCH($A9,Puntos_Jornada!$B$1:$M$1,0)),0) -> 0 | E9: =IFERROR(INDEX(Puntos_Jornada!$B$2:$M$25,MATCH(Plantillas!E9,Puntos_Jornada!$A$2:$A$25,0),MATCH($A9,Puntos_Jornada!$B$1:$M$1,0)),0) -> 0 | F9: =IFERROR(INDEX(Puntos_Jornada!$B$2:$M$25,MATCH(Plantillas!F9,Puntos_Jornada!$A$2:$A$25,0),MATCH($A9,Puntos_Jornada!$B$1:$M$1,0)),0) -> 0 | G9: =IFERROR(INDEX(Puntos_Jornada!$B$2:$M$25,MATCH(Plantillas!G9,Puntos_Jornada!$A$2:$A$25,0),MATCH($A9,Puntos_Jornada!$B$1:$M$1,0)),0) -> 0 | H9: =IFERROR(INDEX(Puntos_Jornada!$B$2:$M$25,MATCH(Plantillas!H9,Puntos_Jornada!$A$2:$A$25,0),MATCH($A9,Puntos_Jornada!$B$1:$M$1,0)),0) -> 0 | I9: =SUM(C9:G9)+H9 -> 0
A10: =Plantillas!A10 -> 1 | B10: =Plantillas!B10 -> Alumno 9 | C10: =IFERROR(INDEX(Puntos_Jornada!$B$2:$M$25,MATCH(Plantillas!C10,Puntos_Jornada!$A$2:$A$25,0),MATCH($A10,Puntos_Jornada!$B$1:$M$1,0)),0) -> 0 | D10: =IFERROR(INDEX(Puntos_Jornada!$B$2:$M$25,MATCH(Plantillas!D10,Puntos_Jornada!$A$2:$A$25,0),MATCH($A10,Puntos_Jornada!$B$1:$M$1,0)),0) -> 0 | E10: =IFERROR(INDEX(Puntos_Jornada!$B$2:$M$25,MATCH(Plantillas!E10,Puntos_Jornada!$A$2:$A$25,0),MATCH($A10,Puntos_Jornada!$B$1:$M$1,0)),0) -> 0 | F10: =IFERROR(INDEX(Puntos_Jornada!$B$2:$M$25,MATCH(Plantillas!F10,Puntos_Jornada!$A$2:$A$25,0),MATCH($A10,Puntos_Jornada!$B$1:$M$1,0)),0) -> 0 | G10: =IFERROR(INDEX(Puntos_Jornada!$B$2:$M$25,MATCH(Plantillas!G10,Puntos_Jornada!$A$2:$A$25,0),MATCH($A10,Puntos_Jornada!$B$1:$M$1,0)),0) -> 0 | H10: =IFERROR(INDEX(Puntos_Jornada!$B$2:$M$25,MATCH(Plantillas!H10,Puntos_Jornada!$A$2:$A$25,0),MATCH($A10,Puntos_Jornada!$B$1:$M$1,0)),0) -> 0 | I10: =SUM(C10:G10)+H10 -> 0
A11: =Plantillas!A11 -> 1 | B11: =Plantillas!B11 -> Alumno 10 | C11: =IFERROR(INDEX(Puntos_Jornada!$B$2:$M$25,MATCH(Plantillas!C11,Puntos_Jornada!$A$2:$A$25,0),MATCH($A11,Puntos_Jornada!$B$1:$M$1,0)),0) -> 0 | D11: =IFERROR(INDEX(Puntos_Jornada!$B$2:$M$25,MATCH(Plantillas!D11,Puntos_Jornada!$A$2:$A$25,0),MATCH($A11,Puntos_Jornada!$B$1:$M$1,0)),0) -> 0 | E11: =IFERROR(INDEX(Puntos_Jornada!$B$2:$M$25,MATCH(Plantillas!E11,Puntos_Jornada!$A$2:$A$25,0),MATCH($A11,Puntos_Jornada!$B$1:$M$1,0)),0) -> 0 | F11: =IFERROR(INDEX(Puntos_Jornada!$B$2:$M$25,MATCH(Plantillas!F11,Puntos_Jornada!$A$2:$A$25,0),MATCH($A11,Puntos_Jornada!$B$1:$M$1,0)),0) -> 0 | G11: =IFERROR(INDEX(Puntos_Jornada!$B$2:$M$25,MATCH(Plantillas!G11,Puntos_Jornada!$A$2:$A$25,0),MATCH($A11,Puntos_Jornada!$B$1:$M$1,0)),0) -> 0 | H11: =IFERROR(INDEX(Puntos_Jornada!$B$2:$M$25,MATCH(Plantillas!H11,Puntos_Jornada!$A$2:$A$25,0),MATCH($A11,Puntos_Jornada!$B$1:$M$1,0)),0) -> 0 | I11: =SUM(C11:G11)+H11 -> 0
A12: =Plantillas!A12 -> 1 | B12: =Plantillas!B12 -> Alumno 11 | C12: =IFERROR(INDEX(Puntos_Jornada!$B$2:$M$25,MATCH(Plantillas!C12,Puntos_Jornada!$A$2:$A$25,0),MATCH($A12,Puntos_Jornada!$B$1:$M$1,0)),0) -> 0 | D12: =IFERROR(INDEX(Puntos_Jornada!$B$2:$M$25,MATCH(Plantillas!D12,Puntos_Jornada!$A$2:$A$25,0),MATCH($A12,Puntos_Jornada!$B$1:$M$1,0)),0) -> 0 | E12: =IFERROR(INDEX(Puntos_Jornada!$B$2:$M$25,MATCH(Plantillas!E12,Puntos_Jornada!$A$2:$A$25,0),MATCH($A12,Puntos_Jornada!$B$1:$M$1,0)),0) -> 0 | F12: =IFERROR(INDEX(Puntos_Jornada!$B$2:$M$25,MATCH(Plantillas!F12,Puntos_Jornada!$A$2:$A$25,0),MATCH($A12,Puntos_Jornada!$B$1:$M$1,0)),0) -> 0 | G12: =IFERROR(INDEX(Puntos_Jornada!$B$2:$M$25,MATCH(Plantillas!G12,Puntos_Jornada!$A$2:$A$25,0),MATCH($A12,Puntos_Jornada!$B$1:$M$1,0)),0) -> 0 | H12: =IFERROR(INDEX(Puntos_Jornada!$B$2:$M$25,MATCH(Plantillas!H12,Puntos_Jornada!$A$2:$A$25,0),MATCH($A12,Puntos_Jornada!$B$1:$M$1,0)),0) -> 0 | I12: =SUM(C12:G12)+H12 -> 0
A13: =Plantillas!A13 -> 1 | B13: =Plantillas!B13 -> Alumno 12 | C13: =IFERROR(INDEX(Puntos_Jornada!$B$2:$M$25,MATCH(Plantillas!C13,Puntos_Jornada!$A$2:$A$25,0),MATCH($A13,Puntos_Jornada!$B$1:$M$1,0)),0) -> 0 | D13: =IFERROR(INDEX(Puntos_Jornada!$B$2:$M$25,MATCH(Plantillas!D13,Puntos_Jornada!$A$2:$A$25,0),MATCH($A13,Puntos_Jornada!$B$1:$M$1,0)),0) -> 0 | E13: =IFERROR(INDEX(Puntos_Jornada!$B$2:$M$25,MATCH(Plantillas!E13,Puntos_Jornada!$A$2:$A$25,0),MATCH($A13,Puntos_Jornada!$B$1:$M$1,0)),0) -> 0 | F13: =IFERROR(INDEX(Puntos_Jornada!$B$2:$M$25,MATCH(Plantillas!F13,Puntos_Jornada!$A$2:$A$25,0),MATCH($A13,Puntos_Jornada!$B$1:$M$1,0)),0) -> 0 | G13: =IFERROR(INDEX(Puntos_Jornada!$B$2:$M$25,MATCH(Plantillas!G13,Puntos_Jornada!$A$2:$A$25,0),MATCH($A13,Puntos_Jornada!$B$1:$M$1,0)),0) -> 0 | H13: =IFERROR(INDEX(Puntos_Jornada!$B$2:$M$25,MATCH(Plantillas!H13,Puntos_Jornada!$A$2:$A$25,0),MATCH($A13,Puntos_Jornada!$B$1:$M$1,0)),0) -> 0 | I13: =SUM(C13:G13)+H13 -> 0
... A289: =Plantillas!A289 -> 12 | B289: =Plantillas!B289 -> Alumno 24 | C289: =IFERROR(INDEX(Puntos_Jornada!$B$2:$M$25,MATCH(Plantillas!C289,Puntos_Jornada!$A$2:$A$25,0),MATCH($A289,Puntos_Jornada!$B$1:$M$1,0)),0) -> 0 | D289: =IFERROR(INDEX(Puntos_Jornada!$B$2:$M$25,MATCH(Plantillas!D289,Puntos_Jornada!$A$2:$A$25,0),MATCH($A289,Puntos_Jornada!$B$1:$M$1,0)),0) -> 0 | E289: =IFERROR(INDEX(Puntos_Jornada!$B$2:$M$25,MATCH(Plantillas!E289,Puntos_Jornada!$A$2:$A$25,0),MATCH($A289,Puntos_Jornada!$B$1:$M$1,0)),0) -> 0 | F289: =IFERROR(INDEX(Puntos_Jornada!$B$2:$M$25,MATCH(Plantillas!F289,Puntos_Jornada!$A$2:$A$25,0),MATCH($A289,Puntos_Jornada!$B$1:$M$1,0)),0) -> 0 | G289: =IFERROR(INDEX(Puntos_Jornada!$B$2:$M$25,MATCH(Plantillas!G289,Puntos_Jornada!$A$2:$A$25,0),MATCH($A289,Puntos_Jornada!$B$1:$M$1,0)),0) -> 0 | H289: =IFERROR(INDEX(Puntos_Jornada!$B$2:$M$25,MATCH(Plantillas!H289,Puntos_Jornada!$A$2:$A$25,0),MATCH($A289,Puntos_Jornada!$B$1:$M$1,0)),0) -> 0 | I289: =SUM(C289:G289)+H289 -> 0

Sheet Clasificacion_General
A1: Manager | B1: Puntos totales temporada | C1: Posición
A2: =Alumnos!B2 -> Alumno 1 | B2: =SUMIFS(Clasificacion!$I$2:$I$289,Clasificacion!$B$2:$B$289,A2) -> 24 | C2: =RANK(B2,$B$2:$B$25,0) -> 1
A3: =Alumnos!B3 -> Alumno 2 | B3: =SUMIFS(Clasificacion!$I$2:$I$289,Clasificacion!$B$2:$B$289,A3) -> 0 | C3: =RANK(B3,$B$2:$B$25,0) -> 2
A4: =Alumnos!B4 -> Alumno 3 | B4: =SUMIFS(Clasificacion!$I$2:$I$289,Clasificacion!$B$2:$B$289,A4) -> 0 | C4: =RANK(B4,$B$2:$B$25,0) -> 2
A5: =Alumnos!B5 -> Alumno 4 | B5: =SUMIFS(Clasificacion!$I$2:$I$289,Clasificacion!$B$2:$B$289,A5) -> 0 | C5: =RANK(B5,$B$2:$B$25,0) -> 2
A6: =Alumnos!B6 -> Alumno 5 | B6: =SUMIFS(Clasificacion!$I$2:$I$289,Clasificacion!$B$2:$B$289,A6) -> 0 | C6: =RANK(B6,$B$2:$B$25,0) -> 2
A7: =Alumnos!B7 -> Alumno 6 | B7: =SUMIFS(Clasificacion!$I$2:$I$289,Clasificacion!$B$2:$B$289,A7) -> 0 | C7: =RANK(B7,$B$2:$B$25,0) -> 2
A8: =Alumnos!B8 -> Alumno 7 | B8: =SUMIFS(Clasificacion!$I$2:$I$289,Clasificacion!$B$2:$B$289,A8) -> 0 | C8: =RANK(B8,$B$2:$B$25,0) -> 2
A9: =Alumnos!B9 -> Alumno 8 | B9: =SUMIFS(Clasificacion!$I$2:$I$289,Clasificacion!$B$2:$B$289,A9) -> 0 | C9: =RANK(B9,$B$2:$B$25,0) -> 2
A10: =Alumnos!B10 -> Alumno 9 | B10: =SUMIFS(Clasificacion!$I$2:$I$289,Clasificacion!$B$2:$B$289,A10) -> 0 | C10: =RANK(B10,$B$2:$B$25,0) -> 2
A11: =Alumnos!B11 -> Alumno 10 | B11: =SUMIFS(Clasificacion!$I$2:$I$289,Clasificacion!$B$2:$B$289,A11) -> 0 | C11: =RANK(B11,$B$2:$B$25,0) -> 2
A12: =Alumnos!B12 -> Alumno 11 | B12: =SUMIFS(Clasificacion!$I$2:$I$289,Clasificacion!$B$2:$B$289,A12) -> 0 | C12: =RANK(B12,$B$2:$B$25,0) -> 2
A13: =Alumnos!B13 -> Alumno 12 | B13: =SUMIFS(Clasificacion!$I$2:$I$289,Clasificacion!$B$2:$B$289,A13) -> 0 | C13: =RANK(B13,$B$2:$B$25,0) -> 2
... A25: =Alumnos!B25 -> Alumno 24 | B25: =SUMIFS(Clasificacion!$I$2:$I$289,Clasificacion!$B$2:$B$289,A25) -> 0 | C25: =RANK(B25,$B$2:$B$25,0) -> 2

Sheet Validacion_Seleccion
A1: Alumno | B1: Veces fichado (toda la temporada) | C1: Estado
A2: =Alumnos!B2 -> Alumno 1 | B2: =COUNTIF(Plantillas!$C$2:$C$289,A2)+COUNTIF(Plantillas!$D$2:$D$289,A2)+COUNTIF(Plantillas!$E$2:$E$289,A2)+COUNTIF(Plantillas!$F$2:$F$289,A2)+COUNTIF(Plantillas!$G$2:$G$289,A2) -> 2 | C2: =IF(B2=0,"NO SELECCIONADO","OK") -> OK
A3: =Alumnos!B3 -> Alumno 2 | B3: =COUNTIF(Plantillas!$C$2:$C$289,A3)+COUNTIF(Plantillas!$D$2:$D$289,A3)+COUNTIF(Plantillas!$E$2:$E$289,A3)+COUNTIF(Plantillas!$F$2:$F$289,A3)+COUNTIF(Plantillas!$G$2:$G$289,A3) -> 0 | C3: =IF(B3=0,"NO SELECCIONADO","OK") -> NO SELECCIONADO
A4: =Alumnos!B4 -> Alumno 3 | B4: =COUNTIF(Plantillas!$C$2:$C$289,A4)+COUNTIF(Plantillas!$D$2:$D$289,A4)+COUNTIF(Plantillas!$E$2:$E$289,A4)+COUNTIF(Plantillas!$F$2:$F$289,A4)+COUNTIF(Plantillas!$G$2:$G$289,A4) -> 1 | C4: =IF(B4=0,"NO SELECCIONADO","OK") -> OK
A5: =Alumnos!B5 -> Alumno 4 | B5: =COUNTIF(Plantillas!$C$2:$C$289,A5)+COUNTIF(Plantillas!$D$2:$D$289,A5)+COUNTIF(Plantillas!$E$2:$E$289,A5)+COUNTIF(Plantillas!$F$2:$F$289,A5)+COUNTIF(Plantillas!$G$2:$G$289,A5) -> 1 | C5: =IF(B5=0,"NO SELECCIONADO","OK") -> OK
A6: =Alumnos!B6 -> Alumno 5 | B6: =COUNTIF(Plantillas!$C$2:$C$289,A6)+COUNTIF(Plantillas!$D$2:$D$289,A6)+COUNTIF(Plantillas!$E$2:$E$289,A6)+COUNTIF(Plantillas!$F$2:$F$289,A6)+COUNTIF(Plantillas!$G$2:$G$289,A6) -> 0 | C6: =IF(B6=0,"NO SELECCIONADO","OK") -> NO SELECCIONADO
A7: =Alumnos!B7 -> Alumno 6 | B7: =COUNTIF(Plantillas!$C$2:$C$289,A7)+COUNTIF(Plantillas!$D$2:$D$289,A7)+COUNTIF(Plantillas!$E$2:$E$289,A7)+COUNTIF(Plantillas!$F$2:$F$289,A7)+COUNTIF(Plantillas!$G$2:$G$289,A7) -> 0 | C7: =IF(B7=0,"NO SELECCIONADO","OK") -> NO SELECCIONADO
A8: =Alumnos!B8 -> Alumno 7 | B8: =COUNTIF(Plantillas!$C$2:$C$289,A8)+COUNTIF(Plantillas!$D$2:$D$289,A8)+COUNTIF(Plantillas!$E$2:$E$289,A8)+COUNTIF(Plantillas!$F$2:$F$289,A8)+COUNTIF(Plantillas!$G$2:$G$289,A8) -> 0 | C8: =IF(B8=0,"NO SELECCIONADO","OK") -> NO SELECCIONADO
A9: =Alumnos!B9 -> Alumno 8 | B9: =COUNTIF(Plantillas!$C$2:$C$289,A9)+COUNTIF(Plantillas!$D$2:$D$289,A9)+COUNTIF(Plantillas!$E$2:$E$289,A9)+COUNTIF(Plantillas!$F$2:$F$289,A9)+COUNTIF(Plantillas!$G$2:$G$289,A9) -> 0 | C9: =IF(B9=0,"NO SELECCIONADO","OK") -> NO SELECCIONADO
A10: =Alumnos!B10 -> Alumno 9 | B10: =COUNTIF(Plantillas!$C$2:$C$289,A10)+COUNTIF(Plantillas!$D$2:$D$289,A10)+COUNTIF(Plantillas!$E$2:$E$289,A10)+COUNTIF(Plantillas!$F$2:$F$289,A10)+COUNTIF(Plantillas!$G$2:$G$289,A10) -> 0 | C10: =IF(B10=0,"NO SELECCIONADO","OK") -> NO SELECCIONADO
A11: =Alumnos!B11 -> Alumno 10 | B11: =COUNTIF(Plantillas!$C$2:$C$289,A11)+COUNTIF(Plantillas!$D$2:$D$289,A11)+COUNTIF(Plantillas!$E$2:$E$289,A11)+COUNTIF(Plantillas!$F$2:$F$289,A11)+COUNTIF(Plantillas!$G$2:$G$289,A11) -> 1 | C11: =IF(B11=0,"NO SELECCIONADO","OK") -> OK
A12: =Alumnos!B12 -> Alumno 11 | B12: =COUNTIF(Plantillas!$C$2:$C$289,A12)+COUNTIF(Plantillas!$D$2:$D$289,A12)+COUNTIF(Plantillas!$E$2:$E$289,A12)+COUNTIF(Plantillas!$F$2:$F$289,A12)+COUNTIF(Plantillas!$G$2:$G$289,A12) -> 0 | C12: =IF(B12=0,"NO SELECCIONADO","OK") -> NO SELECCIONADO
A13: =Alumnos!B13 -> Alumno 12 | B13: =COUNTIF(Plantillas!$C$2:$C$289,A13)+COUNTIF(Plantillas!$D$2:$D$289,A13)+COUNTIF(Plantillas!$E$2:$E$289,A13)+COUNTIF(Plantillas!$F$2:$F$289,A13)+COUNTIF(Plantillas!$G$2:$G$289,A13) -> 0 | C13: =IF(B13=0,"NO SELECCIONADO","OK") -> NO SELECCIONADO
... A25: =Alumnos!B25 -> Alumno 24 | B25: =COUNTIF(Plantillas!$C$2:$C$289,A25)+COUNTIF(Plantillas!$D$2:$D$289,A25)+COUNTIF(Plantillas!$E$2:$E$289,A25)+COUNTIF(Plantillas!$F$2:$F$289,A25)+COUNTIF(Plantillas!$G$2:$G$289,A25) -> 0 | C25: =IF(B25=0,"NO SELECCIONADO","OK") -> NO SELECCIONADO
